Exception:
Traceback (most recent call last):
  File "/usr/local/lib/python3.6/site-packages/pip/basecommand.py", line 215, in main
    status = self.run(options, args)
  File "/usr/local/lib/python3.6/site-packages/pip/commands/install.py", line 342, in run
    prefix=options.prefix_path,
  File "/usr/local/lib/python3.6/site-packages/pip/req/req_set.py", line 784, in install
    **kwargs
  File "/usr/local/lib/python3.6/site-packages/pip/req/req_install.py", line 851, in install
    self.move_wheel_files(self.source_dir, root=root, prefix=prefix)
  File "/usr/local/lib/python3.6/site-packages/pip/req/req_install.py", line 1064, in move_wheel_files
    isolated=self.isolated,
  File "/usr/local/lib/python3.6/site-packages/pip/wheel.py", line 513, in move_wheel_files
    with open_for_csv(record, 'r') as record_in:
  File "/usr/local/lib/python3.6/site-packages/pip/wheel.py", line 172, in open_for_csv
    return open(name, mode + bin, **nl)
FileNotFoundError: [Errno 2] No existe el fichero o el directorio: '/home/jlsuarez/.local/lib/python3.6/site-packages/numpy-1.14.5.dist-info/RECORD'
You are using pip version 9.0.1, however version 10.0.1 is available.
You should consider upgrading via the 'pip install --upgrade pip' command.
You are using pip version 9.0.1, however version 10.0.1 is available.
You should consider upgrading via the 'pip install --upgrade pip' command.
Exception:
Traceback (most recent call last):
  File "/usr/local/lib/python3.6/site-packages/pip/basecommand.py", line 215, in main
    status = self.run(options, args)
  File "/usr/local/lib/python3.6/site-packages/pip/commands/install.py", line 342, in run
    prefix=options.prefix_path,
  File "/usr/local/lib/python3.6/site-packages/pip/req/req_set.py", line 784, in install
    **kwargs
  File "/usr/local/lib/python3.6/site-packages/pip/req/req_install.py", line 851, in install
    self.move_wheel_files(self.source_dir, root=root, prefix=prefix)
  File "/usr/local/lib/python3.6/site-packages/pip/req/req_install.py", line 1064, in move_wheel_files
    isolated=self.isolated,
  File "/usr/local/lib/python3.6/site-packages/pip/wheel.py", line 345, in move_wheel_files
    clobber(source, lib_dir, True)
  File "/usr/local/lib/python3.6/site-packages/pip/wheel.py", line 329, in clobber
    os.utime(destfile, (st.st_atime, st.st_mtime))
FileNotFoundError: [Errno 2] No existe el fichero o el directorio
You are using pip version 9.0.1, however version 10.0.1 is available.
You should consider upgrading via the 'pip install --upgrade pip' command.
You are using pip version 9.0.1, however version 10.0.1 is available.
You should consider upgrading via the 'pip install --upgrade pip' command.
You are using pip version 9.0.1, however version 10.0.1 is available.
You should consider upgrading via the 'pip install --upgrade pip' command.
Exception:
Traceback (most recent call last):
  File "/usr/local/lib/python3.6/site-packages/pip/basecommand.py", line 215, in main
    status = self.run(options, args)
  File "/usr/local/lib/python3.6/site-packages/pip/commands/install.py", line 342, in run
    prefix=options.prefix_path,
  File "/usr/local/lib/python3.6/site-packages/pip/req/req_set.py", line 778, in install
    requirement.uninstall(auto_confirm=True)
  File "/usr/local/lib/python3.6/site-packages/pip/req/req_install.py", line 694, in uninstall
    for path in pip.wheel.uninstallation_paths(dist):
  File "/usr/local/lib/python3.6/site-packages/pip/wheel.py", line 534, in unique
    for item in fn(*args, **kw):
  File "/usr/local/lib/python3.6/site-packages/pip/wheel.py", line 553, in uninstallation_paths
    r = csv.reader(FakeFile(dist.get_metadata_lines('RECORD')))
  File "/usr/local/lib/python3.6/site-packages/pip/_vendor/pkg_resources/__init__.py", line 1472, in get_metadata_lines
    return yield_lines(self.get_metadata(name))
  File "/usr/local/lib/python3.6/site-packages/pip/_vendor/pkg_resources/__init__.py", line 1468, in get_metadata
    value = self._get(self._fn(self.egg_info, name))
  File "/usr/local/lib/python3.6/site-packages/pip/_vendor/pkg_resources/__init__.py", line 1577, in _get
    with open(path, 'rb') as stream:
FileNotFoundError: [Errno 2] No existe el fichero o el directorio: '/home/jlsuarez/.local/lib/python3.6/site-packages/setuptools-39.1.0.dist-info/RECORD'
You are using pip version 9.0.1, however version 10.0.1 is available.
You should consider upgrading via the 'pip install --upgrade pip' command.
You are using pip version 9.0.1, however version 10.0.1 is available.
You should consider upgrading via the 'pip install --upgrade pip' command.
/usr/local/lib/python3.6/distutils/dist.py:261: UserWarning: Unknown distribution option: 'project_urls'
  warnings.warn(msg)
Traceback (most recent call last):
  File "test/test_tfg_fix.py", line 12, in <module>
    from utils import datasets as ds
  File "/home/jlsuarez/pyDML/utils/__init__.py", line 4, in <module>
    from .kfold_tester import kfold_tester_supervised_knn
  File "/home/jlsuarez/pyDML/utils/kfold_tester.py", line 16, in <module>
    from dml import(
  File "/home/jlsuarez/pyDML/dml/__init__.py", line 6, in <module>
    from .pca import PCA
ImportError: libpython3.6m.so.1.0: cannot open shared object file: No such file or directory
You are using pip version 9.0.1, however version 10.0.1 is available.
You should consider upgrading via the 'pip install --upgrade pip' command.
You are using pip version 9.0.1, however version 10.0.1 is available.
You should consider upgrading via the 'pip install --upgrade pip' command.
You are using pip version 9.0.1, however version 10.0.1 is available.
You should consider upgrading via the 'pip install --upgrade pip' command.
You are using pip version 9.0.1, however version 10.0.1 is available.
You should consider upgrading via the 'pip install --upgrade pip' command.
You are using pip version 9.0.1, however version 10.0.1 is available.
You should consider upgrading via the 'pip install --upgrade pip' command.
You are using pip version 9.0.1, however version 10.0.1 is available.
You should consider upgrading via the 'pip install --upgrade pip' command.
You are using pip version 9.0.1, however version 10.0.1 is available.
You should consider upgrading via the 'pip install --upgrade pip' command.
error: [Errno 2] No such file or directory: 'dml/ldml.cpython-36m-x86_64-linux-gnu.so'
/usr/local/lib/python3.6/site-packages/sklearn/discriminant_analysis.py:442: UserWarning: The priors do not sum to 1. Renormalizing
  UserWarning)
/usr/local/lib/python3.6/site-packages/sklearn/discriminant_analysis.py:388: UserWarning: Variables are collinear.
  warnings.warn("Variables are collinear.")
/home/jlsuarez/pyDML/dml/dml_algorithm.py:58: ComplexWarning: Casting complex values to real discards the imaginary part
  L = metric_to_linear(self.metric())
/home/jlsuarez/.local/lib/python3.6/site-packages/numpy/core/numeric.py:492: ComplexWarning: Casting complex values to real discards the imaginary part
  return array(a, dtype, copy=False, order=order)
/usr/local/lib/python3.6/site-packages/sklearn/utils/validation.py:433: ComplexWarning: Casting complex values to real discards the imaginary part
  array = np.array(array, dtype=dtype, order=order, copy=copy)
Traceback (most recent call last):
  File "test/test_tfg_fix.py", line 121, in <module>
    folds, _ = ds.reduced_dobscv10(d,f)
  File "/home/jlsuarez/pyDML/utils/datasets.py", line 151, in reduced_dobscv10
    Xt, yt, _ = read_ARFF(test_name,-1)
  File "/home/jlsuarez/pyDML/utils/arff_reader.py", line 53, in read_ARFF
    data, meta = loadarff(file)
  File "/usr/local/lib/python3.6/site-packages/scipy/io/arff/arffread.py", line 539, in loadarff
    ofile = open(f, 'rt')
FileNotFoundError: [Errno 2] No such file or directory: './data/5-fold/winequality-red/winequality-red-5dobscv-2tst.dat.arff'
You are using pip version 9.0.1, however version 10.0.1 is available.
You should consider upgrading via the 'pip install --upgrade pip' command.
You are using pip version 9.0.1, however version 10.0.1 is available.
You should consider upgrading via the 'pip install --upgrade pip' command.
You are using pip version 9.0.1, however version 10.0.1 is available.
You should consider upgrading via the 'pip install --upgrade pip' command.
You are using pip version 9.0.1, however version 10.0.1 is available.
You should consider upgrading via the 'pip install --upgrade pip' command.
You are using pip version 9.0.1, however version 10.0.1 is available.
You should consider upgrading via the 'pip install --upgrade pip' command.
You are using pip version 9.0.1, however version 10.0.1 is available.
You should consider upgrading via the 'pip install --upgrade pip' command.
You are using pip version 9.0.1, however version 10.0.1 is available.
You should consider upgrading via the 'pip install --upgrade pip' command.
error: could not delete 'dml/dml_utils.cpython-36m-x86_64-linux-gnu.so': No such file or directory
/home2/sge/default/spool/node25/job_scripts/247968: línea 24: python3.6: no se encontró la orden
/home2/sge/default/spool/node25/job_scripts/247968: línea 25: python3.6: no se encontró la orden
/home2/sge/default/spool/node25/job_scripts/247968: línea 26: python3.6: no se encontró la orden
/home2/sge/default/spool/node25/job_scripts/247968: línea 27: python3.6: no se encontró la orden
/home2/sge/default/spool/node25/job_scripts/247968: línea 28: python3.6: no se encontró la orden
/home2/sge/default/spool/node25/job_scripts/247968: línea 29: python3.6: no se encontró la orden
/home2/sge/default/spool/node25/job_scripts/247968: línea 30: python3.6: no se encontró la orden
/home2/sge/default/spool/node25/job_scripts/247968: línea 32: python3.6: no se encontró la orden
/home2/sge/default/spool/node25/job_scripts/247968: línea 33: python3.6: no se encontró la orden
/home2/sge/default/spool/node25/job_scripts/247968: línea 35: python3.6: no se encontró la orden
You are using pip version 9.0.1, however version 10.0.1 is available.
You should consider upgrading via the 'pip install --upgrade pip' command.
You are using pip version 9.0.1, however version 10.0.1 is available.
You should consider upgrading via the 'pip install --upgrade pip' command.
You are using pip version 9.0.1, however version 10.0.1 is available.
You should consider upgrading via the 'pip install --upgrade pip' command.
You are using pip version 9.0.1, however version 10.0.1 is available.
You should consider upgrading via the 'pip install --upgrade pip' command.
You are using pip version 9.0.1, however version 10.0.1 is available.
You should consider upgrading via the 'pip install --upgrade pip' command.
You are using pip version 9.0.1, however version 10.0.1 is available.
You should consider upgrading via the 'pip install --upgrade pip' command.
You are using pip version 9.0.1, however version 10.0.1 is available.
You should consider upgrading via the 'pip install --upgrade pip' command.
/usr/local/lib/python3.6/site-packages/sklearn/discriminant_analysis.py:442: UserWarning: The priors do not sum to 1. Renormalizing
  UserWarning)
/usr/local/lib/python3.6/site-packages/sklearn/discriminant_analysis.py:388: UserWarning: Variables are collinear.
  warnings.warn("Variables are collinear.")
/home/jlsuarez/pyDML/dml/dml_algorithm.py:58: ComplexWarning: Casting complex values to real discards the imaginary part
  L = metric_to_linear(self.metric())
/home/jlsuarez/.local/lib/python3.6/site-packages/numpy/core/numeric.py:492: ComplexWarning: Casting complex values to real discards the imaginary part
  return array(a, dtype, copy=False, order=order)
/usr/local/lib/python3.6/site-packages/sklearn/utils/validation.py:433: ComplexWarning: Casting complex values to real discards the imaginary part
  array = np.array(array, dtype=dtype, order=order, copy=copy)
